{"body": "<p>From @ShadowRanger's comment on my question,</p>\n\n<blockquote>\n  <p><code>PYTHONIOENCODING=utf8</code> won't work unless you <code>export</code> it (or prefix the Python launch with it). Otherwise, it's a local variable in <code>bash</code> that isn't inherited in the environment of child processes. <code>export PYTHONIOENCODING=utf-8</code> would both set and export it in <code>bash</code>.</p>\n</blockquote>\n\n<p><code>export PYTHONIOENCODING=utf-8</code> did the trick, UTF-8 characters no longer raise UnicodeEncodeError</p>\n", "tags": ["python", "python-3.x", "unicode", "utf-8", "locale"], "creation_date": 1476813034, "score": 1, "last_activity_date": 1476813034, "answer_id": 40114882, "is_accepted": true, "owner": {"user_id": 1901114, "reputation": 175, "user_type": "registered", "accept_rate": 70, "display_name": "Mirac7", "link": "http://stackoverflow.com/users/1901114/mirac7", "profile_image": "https://www.gravatar.com/avatar/1facc09b0a900910f0aae6a5f35f180a?s=128&d=identicon&r=PG"}, "title": "UnicodeEncodeError in python3", "question_id": 40113507}