{"body": "<p>For everyone getting this problem, it can be anything, like a wrong django configuration or something with de mod_wsgi. \nin my case it was that i needed to build python 3 with the --enable-shared tag.</p>\n\n<p>if this is also your case, you can follow <a href=\"http://unix.stackexchange.com/questions/319388/centos-7-python3-error-while-loading-shared-libraries-libpython3-5m-so-1-0\">this</a>.</p>\n", "tags": ["apache", "python-3.x", "mod-wsgi", "centos7", "django-1.9"], "creation_date": 1477676245, "score": 0, "last_activity_date": 1477676245, "answer_id": 40310441, "is_accepted": false, "owner": {"user_id": 4225225, "reputation": 42, "user_type": "registered", "accept_rate": 100, "display_name": "Izuzvo", "link": "http://stackoverflow.com/users/4225225/izuzvo", "profile_image": "https://graph.facebook.com/1121797331/picture?type=large"}, "title": "RuntimeError: populate() isn&#39;t reentrant on CentOS 7 | django 1.9 | python3", "question_id": 40289137}