{"title": "Program crashes when trying to catch exception", "tags": ["java"], "creation_date": 1477721248, "score": 0, "body": "<p>You have put another call to to nextInt() within the catch block. At that point it is getting a mismatch..hence the crash.</p>\n\n<pre><code>public static Set&lt;Integer&gt; getTicket()\n{\n    int userInput;\nTreeSet&lt;Integer&gt; getNumbers = new TreeSet&lt;Integer&gt;();\nScanner input = new Scanner(System.in);\nSystem.out.println(\"Enter your 6 numbers between 1-40: \");\nfor (int i = 0; i&lt;6 ; i++)\n{\n    try\n    {\n        System.out.print(i+1 + \": \");\n        userInput = input.nextInt();\n         getNumbers.add(userInput);// Place this inside the try block so that only if it is a valid input, it will be added to list.\n    }\n    catch (InputMismatchException e)\n    {\n        System.out.println(\"Invalid\");  \n        i--; //Decrement so that the invalid input is not counted, and that a valid output can be checked for in its place the next time\n       // userInput = input.nextInt(); //Uneccessary line of code\n    }\n\n    }\nSystem.out.println(\"Your ticket was: \" + getNumbers);\nreturn getNumbers;\n}\n</code></pre>\n\n<p>As you need to read the input six times, there is no need to call that method again within the catch block. The next iteration of the loop will  take care of it.</p>\n", "last_activity_date": 1477723440, "answer_id": 40316553, "is_accepted": false, "owner": {"user_id": 2786452, "reputation": 1908, "user_type": "registered", "accept_rate": 46, "display_name": "SoulRayder", "link": "http://stackoverflow.com/users/2786452/soulrayder", "profile_image": "https://i.stack.imgur.com/Lv1Er.jpg?s=128&g=1"}, "last_edit_date": 1477723440, "question_id": 40316537}