{"tags": ["python", "python-3.x", "subprocess"], "is_answered": false, "creation_date": 1474973219, "view_count": 16, "score": 0, "last_activity_date": 1477776288, "title": "Subprocess output after CalledProcessError in python3", "answer_count": 1, "owner": {"user_id": 49128, "reputation": 2732, "user_type": "registered", "accept_rate": 72, "display_name": "benwad", "link": "http://stackoverflow.com/users/49128/benwad", "profile_image": "https://www.gravatar.com/avatar/c7ed65fb7a7bfd0365aa6c329d6048ad?s=128&d=identicon&r=PG"}, "link": "http://stackoverflow.com/questions/39722660/subprocess-output-after-calledprocesserror-in-python3", "question_id": 39722660}