{"tags": ["apache", "python-3.x", "mod-wsgi", "centos7", "django-1.9"], "is_answered": true, "creation_date": 1477583543, "view_count": 25, "score": 1, "last_activity_date": 1477676245, "title": "RuntimeError: populate() isn&#39;t reentrant on CentOS 7 | django 1.9 | python3", "answer_count": 2, "owner": {"user_id": 4225225, "reputation": 42, "user_type": "registered", "accept_rate": 100, "display_name": "Izuzvo", "link": "http://stackoverflow.com/users/4225225/izuzvo", "profile_image": "https://graph.facebook.com/1121797331/picture?type=large"}, "link": "http://stackoverflow.com/questions/40289137/runtimeerror-populate-isnt-reentrant-on-centos-7-django-1-9-python3", "question_id": 40289137}